#VRML_SIM R2023b utf8

EXTERNPROTO "https://raw.githubusercontent.com/cyberbotics/webots/R2023b/projects/objects/backgrounds/protos/TexturedBackground.proto"
EXTERNPROTO "https://raw.githubusercontent.com/cyberbotics/webots/R2023b/projects/objects/backgrounds/protos/TexturedBackgroundLight.proto"
EXTERNPROTO "https://raw.githubusercontent.com/cyberbotics/webots/R2023b/projects/objects/factory/containers/protos/WoodenBox.proto"
EXTERNPROTO "https://raw.githubusercontent.com/cyberbotics/webots/R2023b/projects/objects/floors/protos/Floor.proto"
EXTERNPROTO "https://raw.githubusercontent.com/cyberbotics/webots/R2023b/projects/appearances/protos/TireRubber.proto"

WorldInfo {
}
Viewpoint {
  orientation 0.4491374963701022 -0.12493355924508479 -0.8846847546605238 3.624164497167761
  position 0.9586425279226924 -0.42636375629041984 2.0980834842011338
}
TexturedBackground {
}
TexturedBackgroundLight {
}
WoodenBox {
  translation -0.18 -0.18 0.05
  rotation 0 0 1 0.785398
  size 0.1 0.1 0.1
}
WoodenBox {
  translation 0.34 -0.34 0.05
  name "wooden box(1)"
  size 0.1 0.1 0.1
}
WoodenBox {
  translation 0 0.36 0.05
  name "wooden box(2)"
  size 0.1 0.1 0.1
}
Floor {
  size 1 1
}
Solid {
  translation -0.5 0 0.05
  children [
    DEF Wall1 Shape {
      appearance PBRAppearance {
        baseColor 0 0 1
        roughness 1
        metalness 0.1
      }
      geometry Box {
        size 0.02 1 0.1
      }
    }
  ]
  boundingObject USE Wall1
}
Solid {
  translation 0.5 0 0.05
  children [
    USE Wall1
  ]
  name "solid(1)"
  boundingObject USE Wall1
}
Solid {
  translation 0 0.5 0.05
  rotation 0 0 1 1.5707963267948968
  children [
    USE Wall1
  ]
  name "solid(2)"
  boundingObject USE Wall1
}
Solid {
  translation 0 -0.5 0.05
  rotation 0 0 1 1.5707963267948968
  children [
    USE Wall1
  ]
  name "solid(3)"
  boundingObject USE Wall1
}
Robot {
  translation 0 0 0.33
  children [
    DistanceSensor {
      translation 0.1 0.03 0
      rotation 0 0 1 0.3
      children [
        Shape {
          appearance PBRAppearance {
            baseColor 0 0 1
          }
          geometry Box {
            size 0.01 0.01 0.01
          }
        }
      ]
      name "ds_left"
    }
    DistanceSensor {
      translation 0.1 -0.03 0
      rotation 0 0 1 -0.3
      children [
        Shape {
          appearance PBRAppearance {
            baseColor 0 0 1
          }
          geometry Box {
            size 0.01 0.01 0.01
          }
        }
      ]
      name "ds_right"
    }
    HingeJoint {
      jointParameters HingeJointParameters {
        axis 0 1 0
        anchor 0.05 0.06 0
      }
      device [
        RotationalMotor {
          name "Motor1"
        }
      ]
      endPoint DEF WHEEL1 Solid {
        translation 0.06 0.06 0
        rotation 1 0 0 1.5707963267948968
        children [
          DEF WHEEL Shape {
            appearance TireRubber {
            }
            geometry Cylinder {
              height 0.02
              radius 0.04
            }
          }
        ]
        boundingObject USE WHEEL
        physics DEF WHEEL_PH Physics {
        }
      }
    }
    HingeJoint {
      jointParameters HingeJointParameters {
        axis 0 1 0
        anchor -0.06 0.06 0
      }
      device [
        RotationalMotor {
          name "Motor2"
        }
      ]
      endPoint Solid {
        translation -0.06 0.06 0
        rotation 1 0 0 1.5707963267948968
        children [
          USE WHEEL
        ]
        name "solid(1)"
        boundingObject USE WHEEL
        physics USE WHEEL_PH
      }
    }
    HingeJoint {
      jointParameters HingeJointParameters {
        axis 0 1 0
        anchor -0.06 -0.06 0
      }
      device [
        RotationalMotor {
          name "Motor3"
        }
      ]
      endPoint Solid {
        translation -0.06 -0.06 0
        rotation 1 0 0 1.5707963267948968
        children [
          USE WHEEL
        ]
        name "solid(2)"
        boundingObject USE WHEEL
        physics USE WHEEL_PH
      }
    }
    HingeJoint {
      jointParameters HingeJointParameters {
        axis 0 1 0
        anchor 0.06 -0.06 0
      }
      device [
        RotationalMotor {
          name "Motor4"
        }
      ]
      endPoint Solid {
        translation 0.06 -0.06 0
        rotation 1 0 0 1.5707963267948968
        children [
          USE WHEEL
        ]
        name "solid(3)"
        boundingObject USE WHEEL
        physics USE WHEEL_PH
      }
    }
    Shape {
      appearance PBRAppearance {
        baseColor 1 0 0
      }
      geometry DEF ROBOT Box {
        size 0.2 0.1 0.05
      }
    }
  ]
  boundingObject USE ROBOT
  physics Physics {
  }
  controller "four_wheeled_collision_avoidance"
}
